[2024-10-31T15:52:56.396+0000] {local_task_job_runner.py:120} INFO - ::group::Pre task execution logs
[2024-10-31T15:52:56.408+0000] {taskinstance.py:2076} INFO - Dependencies all met for dep_context=non-requeueable deps ti=<TaskInstance: datapipeline_new.check_schema_of_original_air_data manual__2024-10-31T15:52:41.609885+00:00 [queued]>
[2024-10-31T15:52:56.413+0000] {taskinstance.py:2076} INFO - Dependencies all met for dep_context=requeueable deps ti=<TaskInstance: datapipeline_new.check_schema_of_original_air_data manual__2024-10-31T15:52:41.609885+00:00 [queued]>
[2024-10-31T15:52:56.413+0000] {taskinstance.py:2306} INFO - Starting attempt 1 of 2
[2024-10-31T15:52:56.423+0000] {taskinstance.py:2330} INFO - Executing <Task(PythonOperator): check_schema_of_original_air_data> on 2024-10-31 15:52:41.609885+00:00
[2024-10-31T15:52:56.428+0000] {warnings.py:112} WARNING - /home/***/.local/lib/python3.12/site-packages/***/task/task_runner/standard_task_runner.py:61: DeprecationWarning: This process (pid=111) is multi-threaded, use of fork() may lead to deadlocks in the child.
  pid = os.fork()

[2024-10-31T15:52:56.429+0000] {standard_task_runner.py:63} INFO - Started process 120 to run task
[2024-10-31T15:52:56.430+0000] {standard_task_runner.py:90} INFO - Running: ['***', 'tasks', 'run', 'datapipeline_new', 'check_schema_of_original_air_data', 'manual__2024-10-31T15:52:41.609885+00:00', '--job-id', '85', '--raw', '--subdir', 'DAGS_FOLDER/dag_script.py', '--cfg-path', '/tmp/tmpciwgx7h1']
[2024-10-31T15:52:56.431+0000] {standard_task_runner.py:91} INFO - Job 85: Subtask check_schema_of_original_air_data
[2024-10-31T15:52:56.570+0000] {task_command.py:426} INFO - Running <TaskInstance: datapipeline_new.check_schema_of_original_air_data manual__2024-10-31T15:52:41.609885+00:00 [running]> on host 8b35fed25b46
[2024-10-31T15:52:56.599+0000] {taskinstance.py:2648} INFO - Exporting env vars: AIRFLOW_CTX_DAG_OWNER='MLOPS' AIRFLOW_CTX_DAG_ID='datapipeline_new' AIRFLOW_CTX_TASK_ID='check_schema_of_original_air_data' AIRFLOW_CTX_EXECUTION_DATE='2024-10-31T15:52:41.609885+00:00' AIRFLOW_CTX_TRY_NUMBER='1' AIRFLOW_CTX_DAG_RUN_ID='manual__2024-10-31T15:52:41.609885+00:00'
[2024-10-31T15:52:56.599+0000] {taskinstance.py:430} INFO - ::endgroup::
[2024-10-31T15:52:56.604+0000] {check_schema_original_airpollution.py:34} INFO - Schema saved to /opt/***/custom_schema_original_dataset.json
[2024-10-31T15:52:56.605+0000] {taskinstance.py:441} INFO - ::group::Post task execution logs
[2024-10-31T15:52:56.605+0000] {taskinstance.py:2905} ERROR - Task failed with exception
Traceback (most recent call last):
  File "/home/airflow/.local/lib/python3.12/site-packages/airflow/models/taskinstance.py", line 465, in _execute_task
    result = _execute_callable(context=context, **execute_callable_kwargs)
             ^^^^^^^^^^^^^^^^^^^^^^^^^^^^^^^^^^^^^^^^^^^^^^^^^^^^^^^^^^^^^
  File "/home/airflow/.local/lib/python3.12/site-packages/airflow/models/taskinstance.py", line 432, in _execute_callable
    return execute_callable(context=context, **execute_callable_kwargs)
           ^^^^^^^^^^^^^^^^^^^^^^^^^^^^^^^^^^^^^^^^^^^^^^^^^^^^^^^^^^^^
  File "/home/airflow/.local/lib/python3.12/site-packages/airflow/models/baseoperator.py", line 401, in wrapper
    return func(self, *args, **kwargs)
           ^^^^^^^^^^^^^^^^^^^^^^^^^^^
  File "/home/airflow/.local/lib/python3.12/site-packages/airflow/operators/python.py", line 235, in execute
    return_value = self.execute_callable()
                   ^^^^^^^^^^^^^^^^^^^^^^^
  File "/home/airflow/.local/lib/python3.12/site-packages/airflow/operators/python.py", line 252, in execute_callable
    return self.python_callable(*self.op_args, **self.op_kwargs)
           ^^^^^^^^^^^^^^^^^^^^^^^^^^^^^^^^^^^^^^^^^^^^^^^^^^^^^
  File "/opt/airflow/dags/DataPreprocessing/src/Schema/check_schema_original_airpollution.py", line 74, in main_check_schema_original
    is_valid = load_and_validate_dataset(DATASET_FILE_PATH, SCHEMA_FILE_PATH)
               ^^^^^^^^^^^^^^^^^^^^^^^^^^^^^^^^^^^^^^^^^^^^^^^^^^^^^^^^^^^^^^
  File "/opt/airflow/dags/DataPreprocessing/src/Schema/check_schema_original_airpollution.py", line 56, in load_and_validate_dataset
    data = pd.read_pickle(file_path)
           ^^^^^^^^^^^^^^^^^^^^^^^^^
  File "/home/airflow/.local/lib/python3.12/site-packages/pandas/io/pickle.py", line 189, in read_pickle
    with get_handle(
         ^^^^^^^^^^^
  File "/home/airflow/.local/lib/python3.12/site-packages/pandas/io/common.py", line 872, in get_handle
    handle = open(handle, ioargs.mode)
             ^^^^^^^^^^^^^^^^^^^^^^^^^
FileNotFoundError: [Errno 2] No such file or directory: '/opt/airflow/DataPreprocessing/src/data_store_pkl_files/air_pollution.pkl'
[2024-10-31T15:52:56.609+0000] {taskinstance.py:1206} INFO - Marking task as UP_FOR_RETRY. dag_id=datapipeline_new, task_id=check_schema_of_original_air_data, run_id=manual__2024-10-31T15:52:41.609885+00:00, execution_date=20241031T155241, start_date=20241031T155256, end_date=20241031T155256
[2024-10-31T15:52:56.614+0000] {standard_task_runner.py:110} ERROR - Failed to execute job 85 for task check_schema_of_original_air_data ([Errno 2] No such file or directory: '/opt/airflow/DataPreprocessing/src/data_store_pkl_files/air_pollution.pkl'; 120)
[2024-10-31T15:52:56.620+0000] {local_task_job_runner.py:240} INFO - Task exited with return code 1
[2024-10-31T15:52:56.710+0000] {taskinstance.py:3503} INFO - 0 downstream tasks scheduled from follow-on schedule check
[2024-10-31T15:52:56.711+0000] {local_task_job_runner.py:222} INFO - ::endgroup::
