[2024-11-12T03:00:45.857+0000] {local_task_job_runner.py:120} INFO - ::group::Pre task execution logs
[2024-11-12T03:00:45.871+0000] {taskinstance.py:2076} INFO - Dependencies all met for dep_context=non-requeueable deps ti=<TaskInstance: modeling_pipeline.Random_Forest_model_Validation manual__2024-11-12T02:57:43.130023+00:00 [queued]>
[2024-11-12T03:00:45.875+0000] {taskinstance.py:2076} INFO - Dependencies all met for dep_context=requeueable deps ti=<TaskInstance: modeling_pipeline.Random_Forest_model_Validation manual__2024-11-12T02:57:43.130023+00:00 [queued]>
[2024-11-12T03:00:45.875+0000] {taskinstance.py:2306} INFO - Starting attempt 2 of 2
[2024-11-12T03:00:45.883+0000] {taskinstance.py:2330} INFO - Executing <Task(PythonOperator): Random_Forest_model_Validation> on 2024-11-12 02:57:43.130023+00:00
[2024-11-12T03:00:45.899+0000] {warnings.py:112} WARNING - /home/***/.local/lib/python3.12/site-packages/***/task/task_runner/standard_task_runner.py:61: DeprecationWarning: This process (pid=309) is multi-threaded, use of fork() may lead to deadlocks in the child.
  pid = os.fork()

[2024-11-12T03:00:45.900+0000] {standard_task_runner.py:63} INFO - Started process 318 to run task
[2024-11-12T03:00:45.907+0000] {standard_task_runner.py:90} INFO - Running: ['***', 'tasks', 'run', 'modeling_pipeline', 'Random_Forest_model_Validation', 'manual__2024-11-12T02:57:43.130023+00:00', '--job-id', '1008', '--raw', '--subdir', 'DAGS_FOLDER/dag_script_model.py', '--cfg-path', '/tmp/tmpqvqp_7l_']
[2024-11-12T03:00:45.911+0000] {standard_task_runner.py:91} INFO - Job 1008: Subtask Random_Forest_model_Validation
[2024-11-12T03:00:45.949+0000] {task_command.py:426} INFO - Running <TaskInstance: modeling_pipeline.Random_Forest_model_Validation manual__2024-11-12T02:57:43.130023+00:00 [running]> on host 5039cd089413
[2024-11-12T03:00:46.007+0000] {taskinstance.py:2648} INFO - Exporting env vars: AIRFLOW_CTX_DAG_OWNER='MLOPS' AIRFLOW_CTX_DAG_ID='modeling_pipeline' AIRFLOW_CTX_TASK_ID='Random_Forest_model_Validation' AIRFLOW_CTX_EXECUTION_DATE='2024-11-12T02:57:43.130023+00:00' AIRFLOW_CTX_TRY_NUMBER='2' AIRFLOW_CTX_DAG_RUN_ID='manual__2024-11-12T02:57:43.130023+00:00'
[2024-11-12T03:00:46.008+0000] {taskinstance.py:430} INFO - ::endgroup::
[2024-11-12T03:00:46.037+0000] {logging_mixin.py:188} INFO - Data loaded from /opt/***/dags/DataPreprocessing/src/data_store_pkl_files/test_data/no_anamoly_test_data.pkl.
[2024-11-12T03:00:46.039+0000] {logging_mixin.py:188} INFO - Original Skewness: 0.5082849280995185
[2024-11-12T03:00:46.048+0000] {logging_mixin.py:188} INFO - Log Transformed Skewness: -0.38788987353405835
[2024-11-12T03:00:46.075+0000] {logging_mixin.py:188} INFO - Box-Cox Transformed Skewness: 0.011851083745351043
[2024-11-12T03:00:46.077+0000] {logging_mixin.py:188} INFO - Choosing Box-Cox transformed column.
[2024-11-12T03:00:46.091+0000] {logging_mixin.py:188} INFO - Feature engineering completed and NaN values dropped.
[2024-11-12T03:00:46.139+0000] {logging_mixin.py:188} WARNING - 2024/11/12 03:00:46 WARNING mlflow.utils.git_utils: Failed to import Git (the Git executable is probably not on your PATH), so Git SHA is not available. Error: Failed to initialize: Bad git executable.
The git executable must be specified in one of the following ways:
    - be included in your $PATH
    - be set via $GIT_PYTHON_GIT_EXECUTABLE
    - explicitly set via git.refresh(<full-path-to-git-executable>)

All git commands will error until this is rectified.

This initial message can be silenced or aggravated in the future by setting the
$GIT_PYTHON_REFRESH environment variable. Use one of the following values:
    - quiet|q|silence|s|silent|none|n|0: for no message or exception
    - warn|w|warning|log|l|1: for a warning message (logging level CRITICAL, displayed by default)
    - error|e|exception|raise|r|2: for a raised exception

Example:
    export GIT_PYTHON_REFRESH=quiet
[2024-11-12T03:00:46.177+0000] {taskinstance.py:441} INFO - ::group::Post task execution logs
[2024-11-12T03:00:46.179+0000] {taskinstance.py:2905} ERROR - Task failed with exception
Traceback (most recent call last):
  File "/home/airflow/.local/lib/python3.12/site-packages/airflow/models/taskinstance.py", line 465, in _execute_task
    result = _execute_callable(context=context, **execute_callable_kwargs)
             ^^^^^^^^^^^^^^^^^^^^^^^^^^^^^^^^^^^^^^^^^^^^^^^^^^^^^^^^^^^^^
  File "/home/airflow/.local/lib/python3.12/site-packages/airflow/models/taskinstance.py", line 432, in _execute_callable
    return execute_callable(context=context, **execute_callable_kwargs)
           ^^^^^^^^^^^^^^^^^^^^^^^^^^^^^^^^^^^^^^^^^^^^^^^^^^^^^^^^^^^^
  File "/home/airflow/.local/lib/python3.12/site-packages/airflow/models/baseoperator.py", line 401, in wrapper
    return func(self, *args, **kwargs)
           ^^^^^^^^^^^^^^^^^^^^^^^^^^^
  File "/home/airflow/.local/lib/python3.12/site-packages/airflow/operators/python.py", line 235, in execute
    return_value = self.execute_callable()
                   ^^^^^^^^^^^^^^^^^^^^^^^
  File "/home/airflow/.local/lib/python3.12/site-packages/airflow/operators/python.py", line 252, in execute_callable
    return self.python_callable(*self.op_args, **self.op_kwargs)
           ^^^^^^^^^^^^^^^^^^^^^^^^^^^^^^^^^^^^^^^^^^^^^^^^^^^^^
  File "/opt/airflow/dags/ModelDevelopment/Validation/RandomForest.py", line 179, in main
    y_pred_original = rf_model.evaluate()
                      ^^^^^^^^^^^^^^^^^^^
  File "/opt/airflow/dags/ModelDevelopment/Validation/RandomForest.py", line 111, in evaluate
    y_pred_boxcox = self.model.predict(self.X_test)
                    ^^^^^^^^^^^^^^^^^^^^^^^^^^^^^^^
  File "/home/airflow/.local/lib/python3.12/site-packages/sklearn/ensemble/_forest.py", line 1061, in predict
    check_is_fitted(self)
  File "/home/airflow/.local/lib/python3.12/site-packages/sklearn/utils/validation.py", line 1661, in check_is_fitted
    raise NotFittedError(msg % {"name": type(estimator).__name__})
sklearn.exceptions.NotFittedError: This RandomForestRegressor instance is not fitted yet. Call 'fit' with appropriate arguments before using this estimator.
[2024-11-12T03:00:46.195+0000] {taskinstance.py:1206} INFO - Marking task as FAILED. dag_id=modeling_pipeline, task_id=Random_Forest_model_Validation, run_id=manual__2024-11-12T02:57:43.130023+00:00, execution_date=20241112T025743, start_date=20241112T030045, end_date=20241112T030046
[2024-11-12T03:00:46.203+0000] {standard_task_runner.py:110} ERROR - Failed to execute job 1008 for task Random_Forest_model_Validation (This RandomForestRegressor instance is not fitted yet. Call 'fit' with appropriate arguments before using this estimator.; 318)
[2024-11-12T03:00:46.253+0000] {local_task_job_runner.py:240} INFO - Task exited with return code 1
[2024-11-12T03:00:46.271+0000] {taskinstance.py:3503} INFO - 0 downstream tasks scheduled from follow-on schedule check
[2024-11-12T03:00:46.272+0000] {local_task_job_runner.py:222} INFO - ::endgroup::
