[2024-10-21T23:20:52.223+0000] {local_task_job_runner.py:120} INFO - ::group::Pre task execution logs
[2024-10-21T23:20:52.233+0000] {taskinstance.py:2076} INFO - Dependencies all met for dep_context=non-requeueable deps ti=<TaskInstance: datapipeline_new.download_data_from_api manual__2024-10-21T23:19:38.622597+00:00 [queued]>
[2024-10-21T23:20:52.236+0000] {taskinstance.py:2076} INFO - Dependencies all met for dep_context=requeueable deps ti=<TaskInstance: datapipeline_new.download_data_from_api manual__2024-10-21T23:19:38.622597+00:00 [queued]>
[2024-10-21T23:20:52.236+0000] {taskinstance.py:2306} INFO - Starting attempt 2 of 2
[2024-10-21T23:20:52.241+0000] {taskinstance.py:2330} INFO - Executing <Task(PythonOperator): download_data_from_api> on 2024-10-21 23:19:38.622597+00:00
[2024-10-21T23:20:52.245+0000] {warnings.py:112} WARNING - /home/***/.local/lib/python3.12/site-packages/***/task/task_runner/standard_task_runner.py:61: DeprecationWarning: This process (pid=134) is multi-threaded, use of fork() may lead to deadlocks in the child.
  pid = os.fork()

[2024-10-21T23:20:52.246+0000] {standard_task_runner.py:63} INFO - Started process 143 to run task
[2024-10-21T23:20:52.246+0000] {standard_task_runner.py:90} INFO - Running: ['***', 'tasks', 'run', 'datapipeline_new', 'download_data_from_api', 'manual__2024-10-21T23:19:38.622597+00:00', '--job-id', '12', '--raw', '--subdir', 'DAGS_FOLDER/dag_script.py', '--cfg-path', '/tmp/tmpdpivky3b']
[2024-10-21T23:20:52.248+0000] {standard_task_runner.py:91} INFO - Job 12: Subtask download_data_from_api
[2024-10-21T23:20:52.270+0000] {task_command.py:426} INFO - Running <TaskInstance: datapipeline_new.download_data_from_api manual__2024-10-21T23:19:38.622597+00:00 [running]> on host 6fd357fee1dd
[2024-10-21T23:20:52.475+0000] {taskinstance.py:2648} INFO - Exporting env vars: AIRFLOW_CTX_DAG_OWNER='Srilakshmi_P' AIRFLOW_CTX_DAG_ID='datapipeline_new' AIRFLOW_CTX_TASK_ID='download_data_from_api' AIRFLOW_CTX_EXECUTION_DATE='2024-10-21T23:19:38.622597+00:00' AIRFLOW_CTX_TRY_NUMBER='2' AIRFLOW_CTX_DAG_RUN_ID='manual__2024-10-21T23:19:38.622597+00:00'
[2024-10-21T23:20:52.476+0000] {taskinstance.py:430} INFO - ::endgroup::
[2024-10-21T23:20:52.595+0000] {logging_mixin.py:188} INFO - Available parameters at this location:
[2024-10-21T23:20:52.596+0000] {logging_mixin.py:188} INFO - pm25
[2024-10-21T23:20:52.596+0000] {logging_mixin.py:188} INFO - o3
[2024-10-21T23:20:52.596+0000] {logging_mixin.py:188} INFO - Location ID for Miami-Fort Lauderdale-Miami Beach: 869
[2024-10-21T23:20:53.110+0000] {taskinstance.py:441} INFO - ::group::Post task execution logs
[2024-10-21T23:20:53.111+0000] {taskinstance.py:2905} ERROR - Task failed with exception
Traceback (most recent call last):
  File "/home/airflow/.local/lib/python3.12/site-packages/airflow/models/taskinstance.py", line 465, in _execute_task
    result = _execute_callable(context=context, **execute_callable_kwargs)
             ^^^^^^^^^^^^^^^^^^^^^^^^^^^^^^^^^^^^^^^^^^^^^^^^^^^^^^^^^^^^^
  File "/home/airflow/.local/lib/python3.12/site-packages/airflow/models/taskinstance.py", line 432, in _execute_callable
    return execute_callable(context=context, **execute_callable_kwargs)
           ^^^^^^^^^^^^^^^^^^^^^^^^^^^^^^^^^^^^^^^^^^^^^^^^^^^^^^^^^^^^
  File "/home/airflow/.local/lib/python3.12/site-packages/airflow/models/baseoperator.py", line 401, in wrapper
    return func(self, *args, **kwargs)
           ^^^^^^^^^^^^^^^^^^^^^^^^^^^
  File "/home/airflow/.local/lib/python3.12/site-packages/airflow/operators/python.py", line 235, in execute
    return_value = self.execute_callable()
                   ^^^^^^^^^^^^^^^^^^^^^^^
  File "/home/airflow/.local/lib/python3.12/site-packages/airflow/operators/python.py", line 252, in execute_callable
    return self.python_callable(*self.op_args, **self.op_kwargs)
           ^^^^^^^^^^^^^^^^^^^^^^^^^^^^^^^^^^^^^^^^^^^^^^^^^^^^^
  File "/opt/airflow/dags/DataPreprocessing/src/data_air.py", line 127, in download_data_function
    save_to_csv(air_pollution_data_1, "DataPreprocessing/src/data_store_pkl_files/csv/air_pollution_data_1.csv")
  File "/opt/airflow/dags/DataPreprocessing/src/data_air.py", line 86, in save_to_csv
    df.to_csv(os.path.join(os.getcwd(),filename), index=False)
  File "/home/airflow/.local/lib/python3.12/site-packages/pandas/core/generic.py", line 3902, in to_csv
    return DataFrameRenderer(formatter).to_csv(
           ^^^^^^^^^^^^^^^^^^^^^^^^^^^^^^^^^^^^
  File "/home/airflow/.local/lib/python3.12/site-packages/pandas/io/formats/format.py", line 1152, in to_csv
    csv_formatter.save()
  File "/home/airflow/.local/lib/python3.12/site-packages/pandas/io/formats/csvs.py", line 247, in save
    with get_handle(
         ^^^^^^^^^^^
  File "/home/airflow/.local/lib/python3.12/site-packages/pandas/io/common.py", line 739, in get_handle
    check_parent_directory(str(handle))
  File "/home/airflow/.local/lib/python3.12/site-packages/pandas/io/common.py", line 604, in check_parent_directory
    raise OSError(rf"Cannot save file into a non-existent directory: '{parent}'")
OSError: Cannot save file into a non-existent directory: '/opt/***/DataPreprocessing/src/data_store_pkl_files/csv'
[2024-10-21T23:20:53.117+0000] {taskinstance.py:1206} INFO - Marking task as FAILED. dag_id=datapipeline_new, task_id=download_data_from_api, run_id=manual__2024-10-21T23:19:38.622597+00:00, execution_date=20241021T231938, start_date=20241021T232052, end_date=20241021T232053
[2024-10-21T23:20:53.122+0000] {standard_task_runner.py:110} ERROR - Failed to execute job 12 for task download_data_from_api (Cannot save file into a non-existent directory: '/opt/***/DataPreprocessing/src/data_store_pkl_files/csv'; 143)
[2024-10-21T23:20:53.134+0000] {local_task_job_runner.py:240} INFO - Task exited with return code 1
[2024-10-21T23:20:53.263+0000] {taskinstance.py:3503} INFO - 0 downstream tasks scheduled from follow-on schedule check
[2024-10-21T23:20:53.268+0000] {local_task_job_runner.py:222} INFO - ::endgroup::
